Traceback (most recent call last):
  File "/opt/hostedtoolcache/Python/3.9.16/x64/lib/python3.9/site-packages/jupyter_cache/executors/utils.py", line 58, in single_nb_execution
    executenb(
  File "/opt/hostedtoolcache/Python/3.9.16/x64/lib/python3.9/site-packages/nbclient/client.py", line 1305, in execute
    return NotebookClient(nb=nb, resources=resources, km=km, **kwargs).execute()
  File "/opt/hostedtoolcache/Python/3.9.16/x64/lib/python3.9/site-packages/jupyter_core/utils/__init__.py", line 166, in wrapped
    return loop.run_until_complete(inner)
  File "/opt/hostedtoolcache/Python/3.9.16/x64/lib/python3.9/asyncio/base_events.py", line 647, in run_until_complete
    return future.result()
  File "/opt/hostedtoolcache/Python/3.9.16/x64/lib/python3.9/site-packages/nbclient/client.py", line 705, in async_execute
    await self.async_execute_cell(
  File "/opt/hostedtoolcache/Python/3.9.16/x64/lib/python3.9/site-packages/nbclient/client.py", line 1058, in async_execute_cell
    await self._check_raise_for_error(cell, cell_index, exec_reply)
  File "/opt/hostedtoolcache/Python/3.9.16/x64/lib/python3.9/site-packages/nbclient/client.py", line 914, in _check_raise_for_error
    raise CellExecutionError.from_cell_and_msg(cell, exec_reply_content)
nbclient.exceptions.CellExecutionError: An error occurred while executing the following cell:
------------------
from kora.drive import upload_public
url = upload_public('claisen.mp4')
# then display it
from IPython.display import HTML

HTML(f"""<video src={url} width=300 controls/>""")
------------------


[0;31m---------------------------------------------------------------------------[0m
[0;31mModuleNotFoundError[0m                       Traceback (most recent call last)
Cell [0;32mIn[2], line 1[0m
[0;32m----> 1[0m [38;5;28;01mfrom[39;00m [38;5;21;01mkora[39;00m[38;5;21;01m.[39;00m[38;5;21;01mdrive[39;00m [38;5;28;01mimport[39;00m upload_public
[1;32m      2[0m url [38;5;241m=[39m upload_public([38;5;124m'[39m[38;5;124mclaisen.mp4[39m[38;5;124m'[39m)
[1;32m      3[0m [38;5;66;03m# then display it[39;00m

File [0;32m/opt/hostedtoolcache/Python/3.9.16/x64/lib/python3.9/site-packages/kora/drive.py:11[0m
[1;32m      8[0m [38;5;28;01mfrom[39;00m [38;5;21;01murllib[39;00m[38;5;21;01m.[39;00m[38;5;21;01mrequest[39;00m [38;5;28;01mimport[39;00m urlretrieve
[1;32m      9[0m [38;5;28;01mfrom[39;00m [38;5;21;01murllib[39;00m[38;5;21;01m.[39;00m[38;5;21;01mparse[39;00m [38;5;28;01mimport[39;00m unquote
[0;32m---> 11[0m [38;5;28;01mfrom[39;00m [38;5;21;01mgoogle[39;00m[38;5;21;01m.[39;00m[38;5;21;01mcolab[39;00m[38;5;21;01m.[39;00m[38;5;21;01mdrive[39;00m [38;5;28;01mimport[39;00m mount
[1;32m     14[0m [38;5;28;01mdef[39;00m [38;5;21mauth_drive[39m():
[1;32m     15[0m     [38;5;28;01mfrom[39;00m [38;5;21;01mpydrive[39;00m[38;5;21;01m.[39;00m[38;5;21;01mauth[39;00m [38;5;28;01mimport[39;00m GoogleAuth

[0;31mModuleNotFoundError[0m: No module named 'google'

